EFFFFF
======================================================================
ERROR: setUpModule (test_saw)
----------------------------------------------------------------------
Traceback (most recent call last):
  File "C:\Users\maomz\PycharmProjects\ESA\tests\test_saw.py", line 63, in setUpModule
    saw_14 = SAW(PATH_14)
  File "C:\Users\maomz\PycharmProjects\ESA\esa\saw.py", line 133, in __init__
    self.ntf = tempfile.NamedTemporaryFile(mode='w', suffix='.axd', delete=False)
NameError: name 'tempfile' is not defined

======================================================================
FAIL: C:\Users\maomz\PycharmProjects\ESA\tests\..\docs\rst\snippets\add_lines_2000.rst
Doctest: add_lines_2000.rst
----------------------------------------------------------------------
Traceback (most recent call last):
  File "C:\Users\maomz\.conda\envs\py35\lib\doctest.py", line 2190, in runTest
    raise self.failureException(self.format_failure(new.getvalue()))
AssertionError: Failed doctest test for add_lines_2000.rst
  File "C:\Users\maomz\PycharmProjects\ESA\tests\..\docs\rst\snippets\add_lines_2000.rst", line 0

----------------------------------------------------------------------
File "C:\Users\maomz\PycharmProjects\ESA\tests\..\docs\rst\snippets\add_lines_2000.rst", line 35, in add_lines_2000.rst
Failed example:
    saw=SAW(FileName=CASE_PATH, CreateIfNotFound=True, early_bind=True)
Exception raised:
    Traceback (most recent call last):
      File "C:\Users\maomz\.conda\envs\py35\lib\doctest.py", line 1321, in __run
        compileflags, 1), test.globs)
      File "<doctest add_lines_2000.rst[4]>", line 1, in <module>
        saw=SAW(FileName=CASE_PATH, CreateIfNotFound=True, early_bind=True)
      File "C:\Users\maomz\PycharmProjects\ESA\esa\saw.py", line 133, in __init__
        self.ntf = tempfile.NamedTemporaryFile(mode='w', suffix='.axd', delete=False)
    NameError: name 'tempfile' is not defined
----------------------------------------------------------------------
File "C:\Users\maomz\PycharmProjects\ESA\tests\..\docs\rst\snippets\add_lines_2000.rst", line 75, in add_lines_2000.rst
Failed example:
    line_key_fields = saw.get_key_field_list('branch')
Exception raised:
    Traceback (most recent call last):
      File "C:\Users\maomz\.conda\envs\py35\lib\doctest.py", line 1321, in __run
        compileflags, 1), test.globs)
      File "<doctest add_lines_2000.rst[9]>", line 1, in <module>
        line_key_fields = saw.get_key_field_list('branch')
    NameError: name 'saw' is not defined
----------------------------------------------------------------------
File "C:\Users\maomz\PycharmProjects\ESA\tests\..\docs\rst\snippets\add_lines_2000.rst", line 76, in add_lines_2000.rst
Failed example:
    line_key_fields
Exception raised:
    Traceback (most recent call last):
      File "C:\Users\maomz\.conda\envs\py35\lib\doctest.py", line 1321, in __run
        compileflags, 1), test.globs)
      File "<doctest add_lines_2000.rst[10]>", line 1, in <module>
        line_key_fields
    NameError: name 'line_key_fields' is not defined
----------------------------------------------------------------------
File "C:\Users\maomz\PycharmProjects\ESA\tests\..\docs\rst\snippets\add_lines_2000.rst", line 78, in add_lines_2000.rst
Failed example:
    first_line = saw.GetParametersSingleElement('branch', line_key_fields, line_df.loc[0, line_key_fields].tolist())
Expected:
    Traceback (most recent call last):
      File "<stdin>", line 1, in <module>
      File "C:\Users\myuser\git\ESA\esa\saw.py", line 693, in GetParametersSingleElement
        output = self._call_simauto('GetParametersSingleElement', ObjectType,
      File "C:\Users\myuser\git\ESA\esa\saw.py", line 1227, in _call_simauto
        raise PowerWorldError(output[0])
    esa.saw.PowerWorldError: GetParameters: Object not found
Got:
    Traceback (most recent call last):
      File "C:\Users\maomz\.conda\envs\py35\lib\doctest.py", line 1321, in __run
        compileflags, 1), test.globs)
      File "<doctest add_lines_2000.rst[11]>", line 1, in <module>
        first_line = saw.GetParametersSingleElement('branch', line_key_fields, line_df.loc[0, line_key_fields].tolist())
    NameError: name 'saw' is not defined
----------------------------------------------------------------------
File "C:\Users\maomz\PycharmProjects\ESA\tests\..\docs\rst\snippets\add_lines_2000.rst", line 94, in add_lines_2000.rst
Failed example:
    saw.RunScriptCommand("EnterMode(EDIT);")
Exception raised:
    Traceback (most recent call last):
      File "C:\Users\maomz\.conda\envs\py35\lib\doctest.py", line 1321, in __run
        compileflags, 1), test.globs)
      File "<doctest add_lines_2000.rst[12]>", line 1, in <module>
        saw.RunScriptCommand("EnterMode(EDIT);")
    NameError: name 'saw' is not defined
----------------------------------------------------------------------
File "C:\Users\maomz\PycharmProjects\ESA\tests\..\docs\rst\snippets\add_lines_2000.rst", line 95, in add_lines_2000.rst
Failed example:
    saw.change_and_confirm_params_multiple_element('branch', line_df)
Exception raised:
    Traceback (most recent call last):
      File "C:\Users\maomz\.conda\envs\py35\lib\doctest.py", line 1321, in __run
        compileflags, 1), test.globs)
      File "<doctest add_lines_2000.rst[13]>", line 1, in <module>
        saw.change_and_confirm_params_multiple_element('branch', line_df)
    NameError: name 'saw' is not defined
----------------------------------------------------------------------
File "C:\Users\maomz\PycharmProjects\ESA\tests\..\docs\rst\snippets\add_lines_2000.rst", line 101, in add_lines_2000.rst
Failed example:
    first_line = saw.GetParametersSingleElement('branch', line_key_fields, line_df.loc[0, line_key_fields].tolist())
Exception raised:
    Traceback (most recent call last):
      File "C:\Users\maomz\.conda\envs\py35\lib\doctest.py", line 1321, in __run
        compileflags, 1), test.globs)
      File "<doctest add_lines_2000.rst[14]>", line 1, in <module>
        first_line = saw.GetParametersSingleElement('branch', line_key_fields, line_df.loc[0, line_key_fields].tolist())
    NameError: name 'saw' is not defined
----------------------------------------------------------------------
File "C:\Users\maomz\PycharmProjects\ESA\tests\..\docs\rst\snippets\add_lines_2000.rst", line 102, in add_lines_2000.rst
Failed example:
    first_line
Exception raised:
    Traceback (most recent call last):
      File "C:\Users\maomz\.conda\envs\py35\lib\doctest.py", line 1321, in __run
        compileflags, 1), test.globs)
      File "<doctest add_lines_2000.rst[15]>", line 1, in <module>
        first_line
    NameError: name 'first_line' is not defined
----------------------------------------------------------------------
File "C:\Users\maomz\PycharmProjects\ESA\tests\..\docs\rst\snippets\add_lines_2000.rst", line 112, in add_lines_2000.rst
Failed example:
    saw.exit()
Exception raised:
    Traceback (most recent call last):
      File "C:\Users\maomz\.conda\envs\py35\lib\doctest.py", line 1321, in __run
        compileflags, 1), test.globs)
      File "<doctest add_lines_2000.rst[16]>", line 1, in <module>
        saw.exit()
    NameError: name 'saw' is not defined


======================================================================
FAIL: C:\Users\maomz\PycharmProjects\ESA\tests\..\docs\rst\snippets\simple_graph_2000.rst
Doctest: simple_graph_2000.rst
----------------------------------------------------------------------
Traceback (most recent call last):
  File "C:\Users\maomz\.conda\envs\py35\lib\doctest.py", line 2190, in runTest
    raise self.failureException(self.format_failure(new.getvalue()))
AssertionError: Failed doctest test for simple_graph_2000.rst
  File "C:\Users\maomz\PycharmProjects\ESA\tests\..\docs\rst\snippets\simple_graph_2000.rst", line 0

----------------------------------------------------------------------
File "C:\Users\maomz\PycharmProjects\ESA\tests\..\docs\rst\snippets\simple_graph_2000.rst", line 28, in simple_graph_2000.rst
Failed example:
    saw = SAW(CASE_PATH, early_bind=True)
Exception raised:
    Traceback (most recent call last):
      File "C:\Users\maomz\.conda\envs\py35\lib\doctest.py", line 1321, in __run
        compileflags, 1), test.globs)
      File "<doctest simple_graph_2000.rst[3]>", line 1, in <module>
        saw = SAW(CASE_PATH, early_bind=True)
      File "C:\Users\maomz\PycharmProjects\ESA\esa\saw.py", line 133, in __init__
        self.ntf = tempfile.NamedTemporaryFile(mode='w', suffix='.axd', delete=False)
    NameError: name 'tempfile' is not defined
----------------------------------------------------------------------
File "C:\Users\maomz\PycharmProjects\ESA\tests\..\docs\rst\snippets\simple_graph_2000.rst", line 34, in simple_graph_2000.rst
Failed example:
    kf = saw.get_key_field_list('branch')
Exception raised:
    Traceback (most recent call last):
      File "C:\Users\maomz\.conda\envs\py35\lib\doctest.py", line 1321, in __run
        compileflags, 1), test.globs)
      File "<doctest simple_graph_2000.rst[4]>", line 1, in <module>
        kf = saw.get_key_field_list('branch')
    NameError: name 'saw' is not defined
----------------------------------------------------------------------
File "C:\Users\maomz\PycharmProjects\ESA\tests\..\docs\rst\snippets\simple_graph_2000.rst", line 35, in simple_graph_2000.rst
Failed example:
    kf
Exception raised:
    Traceback (most recent call last):
      File "C:\Users\maomz\.conda\envs\py35\lib\doctest.py", line 1321, in __run
        compileflags, 1), test.globs)
      File "<doctest simple_graph_2000.rst[5]>", line 1, in <module>
        kf
    NameError: name 'kf' is not defined
----------------------------------------------------------------------
File "C:\Users\maomz\PycharmProjects\ESA\tests\..\docs\rst\snippets\simple_graph_2000.rst", line 37, in simple_graph_2000.rst
Failed example:
    branch_df = saw.GetParametersMultipleElement('branch', kf)
Exception raised:
    Traceback (most recent call last):
      File "C:\Users\maomz\.conda\envs\py35\lib\doctest.py", line 1321, in __run
        compileflags, 1), test.globs)
      File "<doctest simple_graph_2000.rst[6]>", line 1, in <module>
        branch_df = saw.GetParametersMultipleElement('branch', kf)
    NameError: name 'saw' is not defined
----------------------------------------------------------------------
File "C:\Users\maomz\PycharmProjects\ESA\tests\..\docs\rst\snippets\simple_graph_2000.rst", line 38, in simple_graph_2000.rst
Failed example:
    branch_df
Exception raised:
    Traceback (most recent call last):
      File "C:\Users\maomz\.conda\envs\py35\lib\doctest.py", line 1321, in __run
        compileflags, 1), test.globs)
      File "<doctest simple_graph_2000.rst[7]>", line 1, in <module>
        branch_df
    NameError: name 'branch_df' is not defined
----------------------------------------------------------------------
File "C:\Users\maomz\PycharmProjects\ESA\tests\..\docs\rst\snippets\simple_graph_2000.rst", line 59, in simple_graph_2000.rst
Failed example:
    graph = nx.from_pandas_edgelist(branch_df, "BusNum", "BusNum:1", create_using=nx.MultiGraph)
Exception raised:
    Traceback (most recent call last):
      File "C:\Users\maomz\.conda\envs\py35\lib\doctest.py", line 1321, in __run
        compileflags, 1), test.globs)
      File "<doctest simple_graph_2000.rst[8]>", line 1, in <module>
        graph = nx.from_pandas_edgelist(branch_df, "BusNum", "BusNum:1", create_using=nx.MultiGraph)
    NameError: name 'branch_df' is not defined
----------------------------------------------------------------------
File "C:\Users\maomz\PycharmProjects\ESA\tests\..\docs\rst\snippets\simple_graph_2000.rst", line 60, in simple_graph_2000.rst
Failed example:
    graph.number_of_nodes()
Exception raised:
    Traceback (most recent call last):
      File "C:\Users\maomz\.conda\envs\py35\lib\doctest.py", line 1321, in __run
        compileflags, 1), test.globs)
      File "<doctest simple_graph_2000.rst[9]>", line 1, in <module>
        graph.number_of_nodes()
    NameError: name 'graph' is not defined
----------------------------------------------------------------------
File "C:\Users\maomz\PycharmProjects\ESA\tests\..\docs\rst\snippets\simple_graph_2000.rst", line 62, in simple_graph_2000.rst
Failed example:
    graph.number_of_edges()
Exception raised:
    Traceback (most recent call last):
      File "C:\Users\maomz\.conda\envs\py35\lib\doctest.py", line 1321, in __run
        compileflags, 1), test.globs)
      File "<doctest simple_graph_2000.rst[10]>", line 1, in <module>
        graph.number_of_edges()
    NameError: name 'graph' is not defined


======================================================================
FAIL: C:\Users\maomz\PycharmProjects\ESA\tests\..\docs\rst\snippets\increase_loading_14.rst
Doctest: increase_loading_14.rst
----------------------------------------------------------------------
Traceback (most recent call last):
  File "C:\Users\maomz\.conda\envs\py35\lib\doctest.py", line 2190, in runTest
    raise self.failureException(self.format_failure(new.getvalue()))
AssertionError: Failed doctest test for increase_loading_14.rst
  File "C:\Users\maomz\PycharmProjects\ESA\tests\..\docs\rst\snippets\increase_loading_14.rst", line 0

----------------------------------------------------------------------
File "C:\Users\maomz\PycharmProjects\ESA\tests\..\docs\rst\snippets\increase_loading_14.rst", line 13, in increase_loading_14.rst
Failed example:
    saw = SAW(CASE_PATH)
Exception raised:
    Traceback (most recent call last):
      File "C:\Users\maomz\.conda\envs\py35\lib\doctest.py", line 1321, in __run
        compileflags, 1), test.globs)
      File "<doctest increase_loading_14.rst[1]>", line 1, in <module>
        saw = SAW(CASE_PATH)
      File "C:\Users\maomz\PycharmProjects\ESA\esa\saw.py", line 133, in __init__
        self.ntf = tempfile.NamedTemporaryFile(mode='w', suffix='.axd', delete=False)
    NameError: name 'tempfile' is not defined
----------------------------------------------------------------------
File "C:\Users\maomz\PycharmProjects\ESA\tests\..\docs\rst\snippets\increase_loading_14.rst", line 19, in increase_loading_14.rst
Failed example:
    kf = saw.get_key_field_list('load')
Exception raised:
    Traceback (most recent call last):
      File "C:\Users\maomz\.conda\envs\py35\lib\doctest.py", line 1321, in __run
        compileflags, 1), test.globs)
      File "<doctest increase_loading_14.rst[2]>", line 1, in <module>
        kf = saw.get_key_field_list('load')
    NameError: name 'saw' is not defined
----------------------------------------------------------------------
File "C:\Users\maomz\PycharmProjects\ESA\tests\..\docs\rst\snippets\increase_loading_14.rst", line 20, in increase_loading_14.rst
Failed example:
    kf
Exception raised:
    Traceback (most recent call last):
      File "C:\Users\maomz\.conda\envs\py35\lib\doctest.py", line 1321, in __run
        compileflags, 1), test.globs)
      File "<doctest increase_loading_14.rst[3]>", line 1, in <module>
        kf
    NameError: name 'kf' is not defined
----------------------------------------------------------------------
File "C:\Users\maomz\PycharmProjects\ESA\tests\..\docs\rst\snippets\increase_loading_14.rst", line 27, in increase_loading_14.rst
Failed example:
    load_frame = saw.GetParametersMultipleElement('load', kf + ['LoadSMW', 'LoadSMVR'])
Exception raised:
    Traceback (most recent call last):
      File "C:\Users\maomz\.conda\envs\py35\lib\doctest.py", line 1321, in __run
        compileflags, 1), test.globs)
      File "<doctest increase_loading_14.rst[4]>", line 1, in <module>
        load_frame = saw.GetParametersMultipleElement('load', kf + ['LoadSMW', 'LoadSMVR'])
    NameError: name 'saw' is not defined
----------------------------------------------------------------------
File "C:\Users\maomz\PycharmProjects\ESA\tests\..\docs\rst\snippets\increase_loading_14.rst", line 28, in increase_loading_14.rst
Failed example:
    load_frame
Exception raised:
    Traceback (most recent call last):
      File "C:\Users\maomz\.conda\envs\py35\lib\doctest.py", line 1321, in __run
        compileflags, 1), test.globs)
      File "<doctest increase_loading_14.rst[5]>", line 1, in <module>
        load_frame
    NameError: name 'load_frame' is not defined
----------------------------------------------------------------------
File "C:\Users\maomz\PycharmProjects\ESA\tests\..\docs\rst\snippets\increase_loading_14.rst", line 46, in increase_loading_14.rst
Failed example:
    load_frame[['LoadSMW', 'LoadSMVR']] *= 1.5
Exception raised:
    Traceback (most recent call last):
      File "C:\Users\maomz\.conda\envs\py35\lib\doctest.py", line 1321, in __run
        compileflags, 1), test.globs)
      File "<doctest increase_loading_14.rst[6]>", line 1, in <module>
        load_frame[['LoadSMW', 'LoadSMVR']] *= 1.5
    NameError: name 'load_frame' is not defined
----------------------------------------------------------------------
File "C:\Users\maomz\PycharmProjects\ESA\tests\..\docs\rst\snippets\increase_loading_14.rst", line 47, in increase_loading_14.rst
Failed example:
    saw.change_parameters_multiple_element_df('load', load_frame)
Exception raised:
    Traceback (most recent call last):
      File "C:\Users\maomz\.conda\envs\py35\lib\doctest.py", line 1321, in __run
        compileflags, 1), test.globs)
      File "<doctest increase_loading_14.rst[7]>", line 1, in <module>
        saw.change_parameters_multiple_element_df('load', load_frame)
    NameError: name 'saw' is not defined
----------------------------------------------------------------------
File "C:\Users\maomz\PycharmProjects\ESA\tests\..\docs\rst\snippets\increase_loading_14.rst", line 48, in increase_loading_14.rst
Failed example:
    saw.SolvePowerFlow()
Exception raised:
    Traceback (most recent call last):
      File "C:\Users\maomz\.conda\envs\py35\lib\doctest.py", line 1321, in __run
        compileflags, 1), test.globs)
      File "<doctest increase_loading_14.rst[8]>", line 1, in <module>
        saw.SolvePowerFlow()
    NameError: name 'saw' is not defined
----------------------------------------------------------------------
File "C:\Users\maomz\PycharmProjects\ESA\tests\..\docs\rst\snippets\increase_loading_14.rst", line 54, in increase_loading_14.rst
Failed example:
    saw.exit()
Exception raised:
    Traceback (most recent call last):
      File "C:\Users\maomz\.conda\envs\py35\lib\doctest.py", line 1321, in __run
        compileflags, 1), test.globs)
      File "<doctest increase_loading_14.rst[9]>", line 1, in <module>
        saw.exit()
    NameError: name 'saw' is not defined


======================================================================
FAIL: C:\Users\maomz\PycharmProjects\ESA\tests\..\docs\rst\snippets\quick_start_14.rst
Doctest: quick_start_14.rst
----------------------------------------------------------------------
Traceback (most recent call last):
  File "C:\Users\maomz\.conda\envs\py35\lib\doctest.py", line 2190, in runTest
    raise self.failureException(self.format_failure(new.getvalue()))
AssertionError: Failed doctest test for quick_start_14.rst
  File "C:\Users\maomz\PycharmProjects\ESA\tests\..\docs\rst\snippets\quick_start_14.rst", line 0

----------------------------------------------------------------------
File "C:\Users\maomz\PycharmProjects\ESA\tests\..\docs\rst\snippets\quick_start_14.rst", line 21, in quick_start_14.rst
Failed example:
    saw = SAW(FileName=CASE_PATH)
Exception raised:
    Traceback (most recent call last):
      File "C:\Users\maomz\.conda\envs\py35\lib\doctest.py", line 1321, in __run
        compileflags, 1), test.globs)
      File "<doctest quick_start_14.rst[1]>", line 1, in <module>
        saw = SAW(FileName=CASE_PATH)
      File "C:\Users\maomz\PycharmProjects\ESA\esa\saw.py", line 133, in __init__
        self.ntf = tempfile.NamedTemporaryFile(mode='w', suffix='.axd', delete=False)
    NameError: name 'tempfile' is not defined
----------------------------------------------------------------------
File "C:\Users\maomz\PycharmProjects\ESA\tests\..\docs\rst\snippets\quick_start_14.rst", line 27, in quick_start_14.rst
Failed example:
    saw.SolvePowerFlow()
Exception raised:
    Traceback (most recent call last):
      File "C:\Users\maomz\.conda\envs\py35\lib\doctest.py", line 1321, in __run
        compileflags, 1), test.globs)
      File "<doctest quick_start_14.rst[2]>", line 1, in <module>
        saw.SolvePowerFlow()
    NameError: name 'saw' is not defined
----------------------------------------------------------------------
File "C:\Users\maomz\PycharmProjects\ESA\tests\..\docs\rst\snippets\quick_start_14.rst", line 34, in quick_start_14.rst
Failed example:
    bus_data = saw.get_power_flow_results('bus')
Exception raised:
    Traceback (most recent call last):
      File "C:\Users\maomz\.conda\envs\py35\lib\doctest.py", line 1321, in __run
        compileflags, 1), test.globs)
      File "<doctest quick_start_14.rst[3]>", line 1, in <module>
        bus_data = saw.get_power_flow_results('bus')
    NameError: name 'saw' is not defined
----------------------------------------------------------------------
File "C:\Users\maomz\PycharmProjects\ESA\tests\..\docs\rst\snippets\quick_start_14.rst", line 35, in quick_start_14.rst
Failed example:
    bus_data
Exception raised:
    Traceback (most recent call last):
      File "C:\Users\maomz\.conda\envs\py35\lib\doctest.py", line 1321, in __run
        compileflags, 1), test.globs)
      File "<doctest quick_start_14.rst[4]>", line 1, in <module>
        bus_data
    NameError: name 'bus_data' is not defined
----------------------------------------------------------------------
File "C:\Users\maomz\PycharmProjects\ESA\tests\..\docs\rst\snippets\quick_start_14.rst", line 56, in quick_start_14.rst
Failed example:
    gen_data = saw.get_power_flow_results('gen')
Exception raised:
    Traceback (most recent call last):
      File "C:\Users\maomz\.conda\envs\py35\lib\doctest.py", line 1321, in __run
        compileflags, 1), test.globs)
      File "<doctest quick_start_14.rst[5]>", line 1, in <module>
        gen_data = saw.get_power_flow_results('gen')
    NameError: name 'saw' is not defined
----------------------------------------------------------------------
File "C:\Users\maomz\PycharmProjects\ESA\tests\..\docs\rst\snippets\quick_start_14.rst", line 57, in quick_start_14.rst
Failed example:
    gen_data
Exception raised:
    Traceback (most recent call last):
      File "C:\Users\maomz\.conda\envs\py35\lib\doctest.py", line 1321, in __run
        compileflags, 1), test.globs)
      File "<doctest quick_start_14.rst[6]>", line 1, in <module>
        gen_data
    NameError: name 'gen_data' is not defined
----------------------------------------------------------------------
File "C:\Users\maomz\PycharmProjects\ESA\tests\..\docs\rst\snippets\quick_start_14.rst", line 72, in quick_start_14.rst
Failed example:
    gen_key_fields = saw.get_key_field_list('gen')
Exception raised:
    Traceback (most recent call last):
      File "C:\Users\maomz\.conda\envs\py35\lib\doctest.py", line 1321, in __run
        compileflags, 1), test.globs)
      File "<doctest quick_start_14.rst[7]>", line 1, in <module>
        gen_key_fields = saw.get_key_field_list('gen')
    NameError: name 'saw' is not defined
----------------------------------------------------------------------
File "C:\Users\maomz\PycharmProjects\ESA\tests\..\docs\rst\snippets\quick_start_14.rst", line 73, in quick_start_14.rst
Failed example:
    gen_key_fields
Exception raised:
    Traceback (most recent call last):
      File "C:\Users\maomz\.conda\envs\py35\lib\doctest.py", line 1321, in __run
        compileflags, 1), test.globs)
      File "<doctest quick_start_14.rst[8]>", line 1, in <module>
        gen_key_fields
    NameError: name 'gen_key_fields' is not defined
----------------------------------------------------------------------
File "C:\Users\maomz\PycharmProjects\ESA\tests\..\docs\rst\snippets\quick_start_14.rst", line 82, in quick_start_14.rst
Failed example:
    params = gen_key_fields + ['GenMW']
Exception raised:
    Traceback (most recent call last):
      File "C:\Users\maomz\.conda\envs\py35\lib\doctest.py", line 1321, in __run
        compileflags, 1), test.globs)
      File "<doctest quick_start_14.rst[9]>", line 1, in <module>
        params = gen_key_fields + ['GenMW']
    NameError: name 'gen_key_fields' is not defined
----------------------------------------------------------------------
File "C:\Users\maomz\PycharmProjects\ESA\tests\..\docs\rst\snippets\quick_start_14.rst", line 84, in quick_start_14.rst
Failed example:
    saw.ChangeParametersMultipleElement(ObjectType='gen', ParamList=params, ValueList=values)
Exception raised:
    Traceback (most recent call last):
      File "C:\Users\maomz\.conda\envs\py35\lib\doctest.py", line 1321, in __run
        compileflags, 1), test.globs)
      File "<doctest quick_start_14.rst[11]>", line 1, in <module>
        saw.ChangeParametersMultipleElement(ObjectType='gen', ParamList=params, ValueList=values)
    NameError: name 'saw' is not defined
----------------------------------------------------------------------
File "C:\Users\maomz\PycharmProjects\ESA\tests\..\docs\rst\snippets\quick_start_14.rst", line 91, in quick_start_14.rst
Failed example:
    new_gen_data = saw.GetParametersMultipleElement(ObjectType='gen', ParamList=params)
Exception raised:
    Traceback (most recent call last):
      File "C:\Users\maomz\.conda\envs\py35\lib\doctest.py", line 1321, in __run
        compileflags, 1), test.globs)
      File "<doctest quick_start_14.rst[12]>", line 1, in <module>
        new_gen_data = saw.GetParametersMultipleElement(ObjectType='gen', ParamList=params)
    NameError: name 'saw' is not defined
----------------------------------------------------------------------
File "C:\Users\maomz\PycharmProjects\ESA\tests\..\docs\rst\snippets\quick_start_14.rst", line 92, in quick_start_14.rst
Failed example:
    new_gen_data
Exception raised:
    Traceback (most recent call last):
      File "C:\Users\maomz\.conda\envs\py35\lib\doctest.py", line 1321, in __run
        compileflags, 1), test.globs)
      File "<doctest quick_start_14.rst[13]>", line 1, in <module>
        new_gen_data
    NameError: name 'new_gen_data' is not defined
----------------------------------------------------------------------
File "C:\Users\maomz\PycharmProjects\ESA\tests\..\docs\rst\snippets\quick_start_14.rst", line 107, in quick_start_14.rst
Failed example:
    saw.SolvePowerFlow()
Exception raised:
    Traceback (most recent call last):
      File "C:\Users\maomz\.conda\envs\py35\lib\doctest.py", line 1321, in __run
        compileflags, 1), test.globs)
      File "<doctest quick_start_14.rst[14]>", line 1, in <module>
        saw.SolvePowerFlow()
    NameError: name 'saw' is not defined
----------------------------------------------------------------------
File "C:\Users\maomz\PycharmProjects\ESA\tests\..\docs\rst\snippets\quick_start_14.rst", line 108, in quick_start_14.rst
Failed example:
    new_bus_data = saw.get_power_flow_results('bus')
Exception raised:
    Traceback (most recent call last):
      File "C:\Users\maomz\.conda\envs\py35\lib\doctest.py", line 1321, in __run
        compileflags, 1), test.globs)
      File "<doctest quick_start_14.rst[15]>", line 1, in <module>
        new_bus_data = saw.get_power_flow_results('bus')
    NameError: name 'saw' is not defined
----------------------------------------------------------------------
File "C:\Users\maomz\PycharmProjects\ESA\tests\..\docs\rst\snippets\quick_start_14.rst", line 110, in quick_start_14.rst
Failed example:
    diff = bus_data[cols] - new_bus_data[cols]
Exception raised:
    Traceback (most recent call last):
      File "C:\Users\maomz\.conda\envs\py35\lib\doctest.py", line 1321, in __run
        compileflags, 1), test.globs)
      File "<doctest quick_start_14.rst[17]>", line 1, in <module>
        diff = bus_data[cols] - new_bus_data[cols]
    NameError: name 'bus_data' is not defined
----------------------------------------------------------------------
File "C:\Users\maomz\PycharmProjects\ESA\tests\..\docs\rst\snippets\quick_start_14.rst", line 111, in quick_start_14.rst
Failed example:
    diff
Exception raised:
    Traceback (most recent call last):
      File "C:\Users\maomz\.conda\envs\py35\lib\doctest.py", line 1321, in __run
        compileflags, 1), test.globs)
      File "<doctest quick_start_14.rst[18]>", line 1, in <module>
        diff
    NameError: name 'diff' is not defined
----------------------------------------------------------------------
File "C:\Users\maomz\PycharmProjects\ESA\tests\..\docs\rst\snippets\quick_start_14.rst", line 139, in quick_start_14.rst
Failed example:
    gen_copy = gen_data.copy(deep=True)
Exception raised:
    Traceback (most recent call last):
      File "C:\Users\maomz\.conda\envs\py35\lib\doctest.py", line 1321, in __run
        compileflags, 1), test.globs)
      File "<doctest quick_start_14.rst[19]>", line 1, in <module>
        gen_copy = gen_data.copy(deep=True)
    NameError: name 'gen_data' is not defined
----------------------------------------------------------------------
File "C:\Users\maomz\PycharmProjects\ESA\tests\..\docs\rst\snippets\quick_start_14.rst", line 140, in quick_start_14.rst
Failed example:
    gen_copy.loc[gen_copy['BusNum'].isin([2, 3, 6]), 'GenMW'] = [0.0, 100.0, 100.0]
Exception raised:
    Traceback (most recent call last):
      File "C:\Users\maomz\.conda\envs\py35\lib\doctest.py", line 1321, in __run
        compileflags, 1), test.globs)
      File "<doctest quick_start_14.rst[20]>", line 1, in <module>
        gen_copy.loc[gen_copy['BusNum'].isin([2, 3, 6]), 'GenMW'] = [0.0, 100.0, 100.0]
    NameError: name 'gen_copy' is not defined
----------------------------------------------------------------------
File "C:\Users\maomz\PycharmProjects\ESA\tests\..\docs\rst\snippets\quick_start_14.rst", line 141, in quick_start_14.rst
Failed example:
    gen_copy
Exception raised:
    Traceback (most recent call last):
      File "C:\Users\maomz\.conda\envs\py35\lib\doctest.py", line 1321, in __run
        compileflags, 1), test.globs)
      File "<doctest quick_start_14.rst[21]>", line 1, in <module>
        gen_copy
    NameError: name 'gen_copy' is not defined
----------------------------------------------------------------------
File "C:\Users\maomz\PycharmProjects\ESA\tests\..\docs\rst\snippets\quick_start_14.rst", line 159, in quick_start_14.rst
Failed example:
    saw.change_and_confirm_params_multiple_element(ObjectType='gen', command_df=gen_copy.drop('GenMVR', axis=1))
Exception raised:
    Traceback (most recent call last):
      File "C:\Users\maomz\.conda\envs\py35\lib\doctest.py", line 1321, in __run
        compileflags, 1), test.globs)
      File "<doctest quick_start_14.rst[22]>", line 1, in <module>
        saw.change_and_confirm_params_multiple_element(ObjectType='gen', command_df=gen_copy.drop('GenMVR', axis=1))
    NameError: name 'saw' is not defined
----------------------------------------------------------------------
File "C:\Users\maomz\PycharmProjects\ESA\tests\..\docs\rst\snippets\quick_start_14.rst", line 166, in quick_start_14.rst
Failed example:
    saw.SolvePowerFlow()
Exception raised:
    Traceback (most recent call last):
      File "C:\Users\maomz\.conda\envs\py35\lib\doctest.py", line 1321, in __run
        compileflags, 1), test.globs)
      File "<doctest quick_start_14.rst[23]>", line 1, in <module>
        saw.SolvePowerFlow()
    NameError: name 'saw' is not defined
----------------------------------------------------------------------
File "C:\Users\maomz\PycharmProjects\ESA\tests\..\docs\rst\snippets\quick_start_14.rst", line 167, in quick_start_14.rst
Failed example:
    new_gen_data = saw.get_power_flow_results('gen')
Exception raised:
    Traceback (most recent call last):
      File "C:\Users\maomz\.conda\envs\py35\lib\doctest.py", line 1321, in __run
        compileflags, 1), test.globs)
      File "<doctest quick_start_14.rst[24]>", line 1, in <module>
        new_gen_data = saw.get_power_flow_results('gen')
    NameError: name 'saw' is not defined
----------------------------------------------------------------------
File "C:\Users\maomz\PycharmProjects\ESA\tests\..\docs\rst\snippets\quick_start_14.rst", line 168, in quick_start_14.rst
Failed example:
    new_gen_data
Exception raised:
    Traceback (most recent call last):
      File "C:\Users\maomz\.conda\envs\py35\lib\doctest.py", line 1321, in __run
        compileflags, 1), test.globs)
      File "<doctest quick_start_14.rst[25]>", line 1, in <module>
        new_gen_data
    NameError: name 'new_gen_data' is not defined
----------------------------------------------------------------------
File "C:\Users\maomz\PycharmProjects\ESA\tests\..\docs\rst\snippets\quick_start_14.rst", line 184, in quick_start_14.rst
Failed example:
    gen_v = saw.GetParametersMultipleElement('gen', gen_key_fields + ['GenRegPUVolt'])
Exception raised:
    Traceback (most recent call last):
      File "C:\Users\maomz\.conda\envs\py35\lib\doctest.py", line 1321, in __run
        compileflags, 1), test.globs)
      File "<doctest quick_start_14.rst[26]>", line 1, in <module>
        gen_v = saw.GetParametersMultipleElement('gen', gen_key_fields + ['GenRegPUVolt'])
    NameError: name 'saw' is not defined
----------------------------------------------------------------------
File "C:\Users\maomz\PycharmProjects\ESA\tests\..\docs\rst\snippets\quick_start_14.rst", line 185, in quick_start_14.rst
Failed example:
    gen_v
Exception raised:
    Traceback (most recent call last):
      File "C:\Users\maomz\.conda\envs\py35\lib\doctest.py", line 1321, in __run
        compileflags, 1), test.globs)
      File "<doctest quick_start_14.rst[27]>", line 1, in <module>
        gen_v
    NameError: name 'gen_v' is not defined
----------------------------------------------------------------------
File "C:\Users\maomz\PycharmProjects\ESA\tests\..\docs\rst\snippets\quick_start_14.rst", line 197, in quick_start_14.rst
Failed example:
    gen_v['GenRegPUVolt'] = 1.0
Exception raised:
    Traceback (most recent call last):
      File "C:\Users\maomz\.conda\envs\py35\lib\doctest.py", line 1321, in __run
        compileflags, 1), test.globs)
      File "<doctest quick_start_14.rst[28]>", line 1, in <module>
        gen_v['GenRegPUVolt'] = 1.0
    NameError: name 'gen_v' is not defined
----------------------------------------------------------------------
File "C:\Users\maomz\PycharmProjects\ESA\tests\..\docs\rst\snippets\quick_start_14.rst", line 198, in quick_start_14.rst
Failed example:
    gen_v
Exception raised:
    Traceback (most recent call last):
      File "C:\Users\maomz\.conda\envs\py35\lib\doctest.py", line 1321, in __run
        compileflags, 1), test.globs)
      File "<doctest quick_start_14.rst[29]>", line 1, in <module>
        gen_v
    NameError: name 'gen_v' is not defined
----------------------------------------------------------------------
File "C:\Users\maomz\PycharmProjects\ESA\tests\..\docs\rst\snippets\quick_start_14.rst", line 206, in quick_start_14.rst
Failed example:
    saw.change_and_confirm_params_multiple_element('gen', gen_v)
Expected:
    Traceback (most recent call last):
      File "<stdin>", line 1, in <module>
      File "C:\Users\myuser\git\ESA\esa\saw.py", line 199, in change_and_confirm_params_multiple_element
        raise CommandNotRespectedError(m)
    esa.saw.CommandNotRespectedError: After calling ChangeParametersMultipleElement, not all parameters were actually changed within PowerWorld. Try again with a different parameter (e.g. use GenVoltSet instead of GenRegPUVolt).
Got:
    Traceback (most recent call last):
      File "C:\Users\maomz\.conda\envs\py35\lib\doctest.py", line 1321, in __run
        compileflags, 1), test.globs)
      File "<doctest quick_start_14.rst[30]>", line 1, in <module>
        saw.change_and_confirm_params_multiple_element('gen', gen_v)
    NameError: name 'saw' is not defined
----------------------------------------------------------------------
File "C:\Users\maomz\PycharmProjects\ESA\tests\..\docs\rst\snippets\quick_start_14.rst", line 221, in quick_start_14.rst
Failed example:
    saw.LoadState()
Expected:
    Traceback (most recent call last):
      File "<stdin>", line 1, in <module>
      File "C:\Users\myuser\git\ESA\esa\saw.py", line 967, in LoadState
        return self._call_simauto('LoadState')
      File "C:\Users\myuser\git\ESA\esa\saw.py", line 1227, in _call_simauto
        raise PowerWorldError(output[0])
    esa.saw.PowerWorldError: LoadState: State hasn't been previously stored.
Got:
    Traceback (most recent call last):
      File "C:\Users\maomz\.conda\envs\py35\lib\doctest.py", line 1321, in __run
        compileflags, 1), test.globs)
      File "<doctest quick_start_14.rst[31]>", line 1, in <module>
        saw.LoadState()
    NameError: name 'saw' is not defined
----------------------------------------------------------------------
File "C:\Users\maomz\PycharmProjects\ESA\tests\..\docs\rst\snippets\quick_start_14.rst", line 238, in quick_start_14.rst
Failed example:
    try:
        saw.LoadState()
    except PowerWorldError:
        print("Oh my, we've encountered a PowerWorldError!")
Exception raised:
    Traceback (most recent call last):
      File "C:\Users\maomz\.conda\envs\py35\lib\doctest.py", line 1321, in __run
        compileflags, 1), test.globs)
      File "<doctest quick_start_14.rst[33]>", line 2, in <module>
        saw.LoadState()
    NameError: name 'saw' is not defined
----------------------------------------------------------------------
File "C:\Users\maomz\PycharmProjects\ESA\tests\..\docs\rst\snippets\quick_start_14.rst", line 251, in quick_start_14.rst
Failed example:
    saw.exit()
Exception raised:
    Traceback (most recent call last):
      File "C:\Users\maomz\.conda\envs\py35\lib\doctest.py", line 1321, in __run
        compileflags, 1), test.globs)
      File "<doctest quick_start_14.rst[34]>", line 1, in <module>
        saw.exit()
    NameError: name 'saw' is not defined


======================================================================
FAIL: C:\Users\maomz\PycharmProjects\ESA\tests\..\docs\rst\snippets\weighted_graph_14.rst
Doctest: weighted_graph_14.rst
----------------------------------------------------------------------
Traceback (most recent call last):
  File "C:\Users\maomz\.conda\envs\py35\lib\doctest.py", line 2190, in runTest
    raise self.failureException(self.format_failure(new.getvalue()))
AssertionError: Failed doctest test for weighted_graph_14.rst
  File "C:\Users\maomz\PycharmProjects\ESA\tests\..\docs\rst\snippets\weighted_graph_14.rst", line 0

----------------------------------------------------------------------
File "C:\Users\maomz\PycharmProjects\ESA\tests\..\docs\rst\snippets\weighted_graph_14.rst", line 23, in weighted_graph_14.rst
Failed example:
    saw = SAW(CASE_PATH, early_bind=True)
Exception raised:
    Traceback (most recent call last):
      File "C:\Users\maomz\.conda\envs\py35\lib\doctest.py", line 1321, in __run
        compileflags, 1), test.globs)
      File "<doctest weighted_graph_14.rst[4]>", line 1, in <module>
        saw = SAW(CASE_PATH, early_bind=True)
      File "C:\Users\maomz\PycharmProjects\ESA\esa\saw.py", line 133, in __init__
        self.ntf = tempfile.NamedTemporaryFile(mode='w', suffix='.axd', delete=False)
    NameError: name 'tempfile' is not defined
----------------------------------------------------------------------
File "C:\Users\maomz\PycharmProjects\ESA\tests\..\docs\rst\snippets\weighted_graph_14.rst", line 32, in weighted_graph_14.rst
Failed example:
    saw.RunScriptCommand(cmd)
Exception raised:
    Traceback (most recent call last):
      File "C:\Users\maomz\.conda\envs\py35\lib\doctest.py", line 1321, in __run
        compileflags, 1), test.globs)
      File "<doctest weighted_graph_14.rst[8]>", line 1, in <module>
        saw.RunScriptCommand(cmd)
    NameError: name 'saw' is not defined
----------------------------------------------------------------------
File "C:\Users\maomz\PycharmProjects\ESA\tests\..\docs\rst\snippets\weighted_graph_14.rst", line 39, in weighted_graph_14.rst
Failed example:
    with open(ybus_file, 'r') as f:
        f.readline()
        f.readline()
        mat_str = f.read()
Exception raised:
    Traceback (most recent call last):
      File "C:\Users\maomz\.conda\envs\py35\lib\doctest.py", line 1321, in __run
        compileflags, 1), test.globs)
      File "<doctest weighted_graph_14.rst[9]>", line 1, in <module>
        with open(ybus_file, 'r') as f:
    FileNotFoundError: [Errno 2] No such file or directory: 'C:\\Users\\maomz\\PycharmProjects\\ESA\\tests\\cases\\ieee_14\\IEEE 14 bus.mat'
----------------------------------------------------------------------
File "C:\Users\maomz\PycharmProjects\ESA\tests\..\docs\rst\snippets\weighted_graph_14.rst", line 51, in weighted_graph_14.rst
Failed example:
    os.remove(ybus_file)
Exception raised:
    Traceback (most recent call last):
      File "C:\Users\maomz\.conda\envs\py35\lib\doctest.py", line 1321, in __run
        compileflags, 1), test.globs)
      File "<doctest weighted_graph_14.rst[10]>", line 1, in <module>
        os.remove(ybus_file)
    FileNotFoundError: [WinError 2] The system cannot find the file specified: 'C:\\Users\\maomz\\PycharmProjects\\ESA\\tests\\cases\\ieee_14\\IEEE 14 bus.mat'
----------------------------------------------------------------------
File "C:\Users\maomz\PycharmProjects\ESA\tests\..\docs\rst\snippets\weighted_graph_14.rst", line 58, in weighted_graph_14.rst
Failed example:
    mat_str = re.sub(r'\s', '', mat_str)
Exception raised:
    Traceback (most recent call last):
      File "C:\Users\maomz\.conda\envs\py35\lib\doctest.py", line 1321, in __run
        compileflags, 1), test.globs)
      File "<doctest weighted_graph_14.rst[11]>", line 1, in <module>
        mat_str = re.sub(r'\s', '', mat_str)
    NameError: name 'mat_str' is not defined
----------------------------------------------------------------------
File "C:\Users\maomz\PycharmProjects\ESA\tests\..\docs\rst\snippets\weighted_graph_14.rst", line 59, in weighted_graph_14.rst
Failed example:
    lines = re.split(';', mat_str)
Exception raised:
    Traceback (most recent call last):
      File "C:\Users\maomz\.conda\envs\py35\lib\doctest.py", line 1321, in __run
        compileflags, 1), test.globs)
      File "<doctest weighted_graph_14.rst[12]>", line 1, in <module>
        lines = re.split(';', mat_str)
    NameError: name 'mat_str' is not defined
----------------------------------------------------------------------
File "C:\Users\maomz\PycharmProjects\ESA\tests\..\docs\rst\snippets\weighted_graph_14.rst", line 70, in weighted_graph_14.rst
Failed example:
    for line in lines:
        match = exp.match(line)
        if match is None:
            continue
        idx1, idx2, real, imag = match.groups()
        if idx1 == idx2:
            continue
        neg_admittance = float(real) + 1j * float(imag)
        try:
            impedance = -1 / neg_admittance
        except ZeroDivisionError:
            continue
        g.add_edge(int(idx1), int(idx2), r=impedance.real, x=impedance.imag)
Exception raised:
    Traceback (most recent call last):
      File "C:\Users\maomz\.conda\envs\py35\lib\doctest.py", line 1321, in __run
        compileflags, 1), test.globs)
      File "<doctest weighted_graph_14.rst[16]>", line 1, in <module>
        for line in lines:
    NameError: name 'lines' is not defined
----------------------------------------------------------------------
File "C:\Users\maomz\PycharmProjects\ESA\tests\..\docs\rst\snippets\weighted_graph_14.rst", line 89, in weighted_graph_14.rst
Failed example:
    g.number_of_nodes()
Expected:
    14
Got:
    0
----------------------------------------------------------------------
File "C:\Users\maomz\PycharmProjects\ESA\tests\..\docs\rst\snippets\weighted_graph_14.rst", line 91, in weighted_graph_14.rst
Failed example:
    g.number_of_edges()
Expected:
    20
Got:
    0
----------------------------------------------------------------------
File "C:\Users\maomz\PycharmProjects\ESA\tests\..\docs\rst\snippets\weighted_graph_14.rst", line 94, in weighted_graph_14.rst
Failed example:
    data_1_2['r']
Exception raised:
    Traceback (most recent call last):
      File "C:\Users\maomz\.conda\envs\py35\lib\doctest.py", line 1321, in __run
        compileflags, 1), test.globs)
      File "<doctest weighted_graph_14.rst[20]>", line 1, in <module>
        data_1_2['r']
    TypeError: 'NoneType' object is not subscriptable
----------------------------------------------------------------------
File "C:\Users\maomz\PycharmProjects\ESA\tests\..\docs\rst\snippets\weighted_graph_14.rst", line 96, in weighted_graph_14.rst
Failed example:
    data_1_2['x']
Exception raised:
    Traceback (most recent call last):
      File "C:\Users\maomz\.conda\envs\py35\lib\doctest.py", line 1321, in __run
        compileflags, 1), test.globs)
      File "<doctest weighted_graph_14.rst[21]>", line 1, in <module>
        data_1_2['x']
    TypeError: 'NoneType' object is not subscriptable
----------------------------------------------------------------------
File "C:\Users\maomz\PycharmProjects\ESA\tests\..\docs\rst\snippets\weighted_graph_14.rst", line 103, in weighted_graph_14.rst
Failed example:
    saw.exit()
Exception raised:
    Traceback (most recent call last):
      File "C:\Users\maomz\.conda\envs\py35\lib\doctest.py", line 1321, in __run
        compileflags, 1), test.globs)
      File "<doctest weighted_graph_14.rst[22]>", line 1, in <module>
        saw.exit()
    NameError: name 'saw' is not defined


----------------------------------------------------------------------
Ran 5 tests in 23.064s

FAILED (failures=5, errors=1)
